{"suggestions":[{"command_executed":"python_test.py ","error":"Traceback (most recent call last):\n  File \"python_test.py\", line 10, in <module>\n    print(test[\"a\"])\nKeyError: 'a'\n","prompt":"I tried running this python unit test:\n        python_test.py \n        and received error message:\n        Traceback (most recent call last):\n  File \"python_test.py\", line 10, in <module>\n    print(test[\"a\"])\nKeyError: 'a'\n\n        How can I solve this error?","output":"\n\nThe error message indicates that the key 'a' is not present in the dictionary 'test'. To solve this error, you can either add the key 'a' to the dictionary 'test' or check if the key 'a' is present in the dictionary before trying to access it."},{"command_executed":"javascript_test.js ","error":"node:assert:400\n    throw err;\n    ^\n\nAssertionError [ERR_ASSERTION]: The expression evaluated to a falsy value:\n\n  assert(1 === \"one\")\n\n    at assert_test (/Users/demouser/Projects/demo/javascript_test.js:4:5)\n    at Object.<anonymous> (/Users/demouser/Projects/demo/javascript_test.js:7:1)\n    at Module._compile (node:internal/modules/cjs/loader:1159:14)\n    at Module._extensions..js (node:internal/modules/cjs/loader:1213:10)\n    at Module.load (node:internal/modules/cjs/loader:1037:32)\n    at Module._load (node:internal/modules/cjs/loader:878:12)\n    at Function.executeUserEntryPoint [as runMain] (node:internal/modules/run_main:81:12)\n    at node:internal/main/run_main_module:23:47 {\n  generatedMessage: true,\n  code: 'ERR_ASSERTION',\n  actual: false,\n  expected: true,\n  operator: '=='\n}\n\nNode.js v18.12.1\n(.venv) ","prompt":"I tried running this node unit test:\n        javascript_test.js \n        and received error message:\n        node:assert:400\n    throw err;\n    ^\n\nAssertionError [ERR_ASSERTION]: The expression evaluated to a falsy value:\n\n  assert(1 === \"one\")\n\n    at assert_test (/Users/demouser/Projects/demo/javascript_test.js:4:5)\n    at Object.<anonymous> (/Users/demouser/Projects/demo/javascript_test.js:7:1)\n    at Module._compile (node:internal/modules/cjs/loader:1159:14)\n    at Module._extensions..js (node:internal/modules/cjs/loader:1213:10)\n    at Module.load (node:internal/modules/cjs/loader:1037:32)\n    at Module._load (node:internal/modules/cjs/loader:878:12)\n    at Function.executeUserEntryPoint [as runMain] (node:internal/modules/run_main:81:12)\n    at node:internal/main/run_main_module:23:47 {\n  generatedMessage: true,\n  code: 'ERR_ASSERTION',\n  actual: false,\n  expected: true,\n  operator: '=='\n}\n\nNode.js v18.12.1\n(.venv) \n        How can I solve this error?","output":"\n\nThis error is caused by an assertion failure in your code. An assertion is a statement that checks if a condition is true. In this case, the assertion is checking if 1 is equal to \"one\". Since 1 is not equal to \"one\", the assertion fails and an error is thrown.\n\nTo solve this error, you need to make sure that the assertion is valid. In this case, you should change the assertion to check if 1 is equal to 1 instead of \"one"},{"command_executed":"tests/test_meetings.py ","error":"==================================== test session starts =====================================\nplatform darwin -- Python 3.8.5, pytest-7.1.2, pluggy-1.0.0\nrootdir: /Users/demouser/meetingsproject, configfile: pyproject.toml\ncollected 596 items                                                                          \n\ntests/test_meetings.py F........................................................ [  9%]\n...................................................................................... [ 23%]\n...................................................................................... [ 38%]\n...................................................................................... [ 52%]\n...................................................................................... [ 67%]\n...................................................................................... [ 81%]\n...................................................................................... [ 96%]\n.......................                                                                [100%]\n\n========================================== FAILURES ==========================================\n______________________________________ test_item_count _______________________________________\n\n    def test_item_count():\n>       assert len(parsed_items) == 3423\nE       AssertionError: assert 584 == 3423\nE        +  where 584 = len([{'all_day': False,\\n 'classification': 'City Council',\\n 'created': FakeDatetime(2022, 3, 1, 0, 0),\\n 'description': '',...passed',\\n 'time_notes': '',\\n 'title': 'Regular City Council Meeting',\\n 'updated': FakeDatetime(2022, 3, 1, 0, 0)}, ...])\n\ntests/test_meetings.py:34: AssertionError\n================================== short test summary info ===================================\nFAILED tests/test_meetings.py::test_item_count - AssertionError: assert 584 == 3423\n=============================== 1 failed, 595 passed in 4.92s ================================\n","prompt":"I tried running this pytest unit test:\n        tests/test_meetings.py \n        and received error message:\n        ==================================== test session starts =====================================\nplatform darwin -- Python 3.8.5, pytest-7.1.2, pluggy-1.0.0\nrootdir: /Users/demouser/meetingsproject, configfile: pyproject.toml\ncollected 596 items                                                                          \n\ntests/test_meetings.py F........................................................ [  9%]\n...................................................................................... [ 23%]\n...................................................................................... [ 38%]\n...................................................................................... [ 52%]\n...................................................................................... [ 67%]\n...................................................................................... [ 81%]\n...................................................................................... [ 96%]\n.......................                                                                [100%]\n\n========================================== FAILURES ==========================================\n______________________________________ test_item_count _______________________________________\n\n    def test_item_count():\n>       assert len(parsed_items) == 3423\nE       AssertionError: assert 584 == 3423\nE        +  where 584 = len([{'all_day': False,\\n 'classification': 'City Council',\\n 'created': FakeDatetime(2022, 3, 1, 0, 0),\\n 'description': '',...passed',\\n 'time_notes': '',\\n 'title': 'Regular City Council Meeting',\\n 'updated': FakeDatetime(2022, 3, 1, 0, 0)}, ...])\n\ntests/test_meetings.py:34: AssertionError\n================================== short test summary info ===================================\nFAILED tests/test_meetings.py::test_item_count - AssertionError: assert 584 == 3423\n=============================== 1 failed, 595 passed in 4.92s ================================\n\n        How can I solve this error?","output":"\n\nThe error message indicates that the assertion in the test_item_count() function is failing. This means that the expected value (3423) does not match the actual value (584). To solve this error, you need to modify the test_item_count() function so that it is expecting the correct value."},{"command_executed":"search openstates ","error":"ERROR: Exception:\nTraceback (most recent call last):\n  File \"/Users/demouser/miniconda3/lib/python3.8/site-packages/pip/_internal/cli/base_command.py\", line 228, in _main\n    status = self.run(options, args)\n  File \"/Users/demouser/miniconda3/lib/python3.8/site-packages/pip/_internal/commands/search.py\", line 60, in run\n    pypi_hits = self.search(query, options)\n  File \"/Users/demouser/miniconda3/lib/python3.8/site-packages/pip/_internal/commands/search.py\", line 80, in search\n    hits = pypi.search({'name': query, 'summary': query}, 'or')\n  File \"/Users/demouser/miniconda3/lib/python3.8/xmlrpc/client.py\", line 1109, in __call__\n    return self.__send(self.__name, args)\n  File \"/Users/demouser/miniconda3/lib/python3.8/xmlrpc/client.py\", line 1450, in __request\n    response = self.__transport.request(\n  File \"/Users/demouser/miniconda3/lib/python3.8/site-packages/pip/_internal/network/xmlrpc.py\", line 45, in request\n    return self.parse_response(response.raw)\n  File \"/Users/demouser/miniconda3/lib/python3.8/xmlrpc/client.py\", line 1341, in parse_response\n    return u.close()\n  File \"/Users/demouser/miniconda3/lib/python3.8/xmlrpc/client.py\", line 655, in close\n    raise Fault(**self._stack[0])\nxmlrpc.client.Fault: <Fault -32500: \"RuntimeError: PyPI no longer supports 'pip search' (or XML-RPC search). Please use https://pypi.org/search (via a browser) instead. See https://warehouse.pypa.io/api-reference/xml-rpc.html#deprecated-methods for more information.\">\n","prompt":"I tried running this pip unit test:\n        search openstates \n        and received error message:\n        ERROR: Exception:\nTraceback (most recent call last):\n  File \"/Users/demouser/miniconda3/lib/python3.8/site-packages/pip/_internal/cli/base_command.py\", line 228, in _main\n    status = self.run(options, args)\n  File \"/Users/demouser/miniconda3/lib/python3.8/site-packages/pip/_internal/commands/search.py\", line 60, in run\n    pypi_hits = self.search(query, options)\n  File \"/Users/demouser/miniconda3/lib/python3.8/site-packages/pip/_internal/commands/search.py\", line 80, in search\n    hits = pypi.search({'name': query, 'summary': query}, 'or')\n  File \"/Users/demouser/miniconda3/lib/python3.8/xmlrpc/client.py\", line 1109, in __call__\n    return self.__send(self.__name, args)\n  File \"/Users/demouser/miniconda3/lib/python3.8/xmlrpc/client.py\", line 1450, in __request\n    response = self.__transport.request(\n  File \"/Users/demouser/miniconda3/lib/python3.8/site-packages/pip/_internal/network/xmlrpc.py\", line 45, in request\n    return self.parse_response(response.raw)\n  File \"/Users/demouser/miniconda3/lib/python3.8/xmlrpc/client.py\", line 1341, in parse_response\n    return u.close()\n  File \"/Users/demouser/miniconda3/lib/python3.8/xmlrpc/client.py\", line 655, in close\n    raise Fault(**self._stack[0])\nxmlrpc.client.Fault: <Fault -32500: \"RuntimeError: PyPI no longer supports 'pip search' (or XML-RPC search). Please use https://pypi.org/search (via a browser) instead. See https://warehouse.pypa.io/api-reference/xml-rpc.html#deprecated-methods for more information.\">\n\n        How can I solve this error?","output":"\n\nThe error message is telling you that PyPI no longer supports 'pip search' or XML-RPC search. You should use the https://pypi.org/search website (via a browser) instead. See the link provided in the error message for more information."},{"command_executed":"i react-swipeable-views ","error":"npm ERR! code ERESOLVE\nnpm ERR! ERESOLVE unable to resolve dependency tree\nnpm ERR! \nnpm ERR! While resolving: web@0.1.0\nnpm ERR! Found: react@18.2.0\nnpm ERR! node_modules/react\nnpm ERR!   react@\"^18.2.0\" from the root project\nnpm ERR! \nnpm ERR! Could not resolve dependency:\nnpm ERR! peer react@\"^15.3.0 || ^16.0.0 || ^17.0.0\" from react-swipeable-views@0.14.0\nnpm ERR! node_modules/react-swipeable-views\nnpm ERR!   react-swipeable-views@\"*\" from the root project\nnpm ERR! \nnpm ERR! Fix the upstream dependency conflict, or retry\nnpm ERR! this command with --force, or --legacy-peer-deps\nnpm ERR! to accept an incorrect (and potentially broken) dependency resolution.\nnpm ERR! \nnpm ERR! See /home/demouser/.npm/eresolve-report.txt for a full report.\n\nnpm ERR! A complete log of this run can be found in:\nnpm ERR!     /home/demouser/.npm/_logs/2022-08-04T16_50_51_600Z-debug-0.log\n","prompt":"I tried running this npm unit test:\n        i react-swipeable-views \n        and received error message:\n        npm ERR! code ERESOLVE\nnpm ERR! ERESOLVE unable to resolve dependency tree\nnpm ERR! \nnpm ERR! While resolving: web@0.1.0\nnpm ERR! Found: react@18.2.0\nnpm ERR! node_modules/react\nnpm ERR!   react@\"^18.2.0\" from the root project\nnpm ERR! \nnpm ERR! Could not resolve dependency:\nnpm ERR! peer react@\"^15.3.0 || ^16.0.0 || ^17.0.0\" from react-swipeable-views@0.14.0\nnpm ERR! node_modules/react-swipeable-views\nnpm ERR!   react-swipeable-views@\"*\" from the root project\nnpm ERR! \nnpm ERR! Fix the upstream dependency conflict, or retry\nnpm ERR! this command with --force, or --legacy-peer-deps\nnpm ERR! to accept an incorrect (and potentially broken) dependency resolution.\nnpm ERR! \nnpm ERR! See /home/demouser/.npm/eresolve-report.txt for a full report.\n\nnpm ERR! A complete log of this run can be found in:\nnpm ERR!     /home/demouser/.npm/_logs/2022-08-04T16_50_51_600Z-debug-0.log\n\n        How can I solve this error?","output":"\n\nTo solve this error, you can try running the command with the --force or --legacy-peer-deps flags. This will allow you to accept an incorrect (and potentially broken) dependency resolution. You can also try to fix the upstream dependency conflict by manually updating the version of React that is being used."}]}