{"suggestions":[{"command_executed":"python_test.py ","error":"Traceback (most recent call last):\n  File \"python_test.py\", line 10, in <module>\n    print(test[\"a\"])\nKeyError: 'a'\n","prompt":"I tried running this python unit test:\n        python_test.py \n        and received error message:\n        Traceback (most recent call last):\n  File \"python_test.py\", line 10, in <module>\n    print(test[\"a\"])\nKeyError: 'a'\n\n        Help me understand this error and explain how I can solve this error.","output":"\n\nThis error means that the key 'a' was not found in the test dictionary. A KeyError is a type of error that occurs when a dictionary key is not found in the dictionary. In this case, it looks like you were trying to access the value associated with the key \"a\" in the test dictionary, but no such key exists.\n\nIn order to solve this error you can either make sure that key \"a\" is present in the dictionary or you can use the dict.get() method to access the value associated with the key. The get() method will either return the value associated with the key or return None if no key exists.\n\nExample: \ntest = {\"a\": 1, \"b\": 2}\n\nvalue = test.get(\"a\") #returns 1\nvalue2 = test.get(\"c\") #returns None"},{"command_executed":"javascript_test.js ","error":"node:assert:400\n    throw err;\n    ^\n\nAssertionError [ERR_ASSERTION]: The expression evaluated to a falsy value:\n\n  assert(1 === \"one\")\n\n    at assert_test (/Users/demouser/Projects/demo/javascript_test.js:4:5)\n    at Object.<anonymous> (/Users/demouser/Projects/demo/javascript_test.js:7:1)\n    at Module._compile (node:internal/modules/cjs/loader:1159:14)\n    at Module._extensions..js (node:internal/modules/cjs/loader:1213:10)\n    at Module.load (node:internal/modules/cjs/loader:1037:32)\n    at Module._load (node:internal/modules/cjs/loader:878:12)\n    at Function.executeUserEntryPoint [as runMain] (node:internal/modules/run_main:81:12)\n    at node:internal/main/run_main_module:23:47 {\n  generatedMessage: true,\n  code: 'ERR_ASSERTION',\n  actual: false,\n  expected: true,\n  operator: '=='\n}\n\nNode.js v18.12.1\n(.venv) ","prompt":"I tried running this node unit test:\n        javascript_test.js \n        and received error message:\n        node:assert:400\n    throw err;\n    ^\n\nAssertionError [ERR_ASSERTION]: The expression evaluated to a falsy value:\n\n  assert(1 === \"one\")\n\n    at assert_test (/Users/demouser/Projects/demo/javascript_test.js:4:5)\n    at Object.<anonymous> (/Users/demouser/Projects/demo/javascript_test.js:7:1)\n    at Module._compile (node:internal/modules/cjs/loader:1159:14)\n    at Module._extensions..js (node:internal/modules/cjs/loader:1213:10)\n    at Module.load (node:internal/modules/cjs/loader:1037:32)\n    at Module._load (node:internal/modules/cjs/loader:878:12)\n    at Function.executeUserEntryPoint [as runMain] (node:internal/modules/run_main:81:12)\n    at node:internal/main/run_main_module:23:47 {\n  generatedMessage: true,\n  code: 'ERR_ASSERTION',\n  actual: false,\n  expected: true,\n  operator: '=='\n}\n\nNode.js v18.12.1\n(.venv) \n        Help me understand this error and explain how I can solve this error.","output":"\n\nThis error is caused by an assertion that has failed. Assertions are used by Node.js to check that certain conditions are met before executing a certain part of code. In this case, the assertion is saying that the two values should be equal, but they are not (1 === \"one\").\n\nTo solve this problem, look at the code that caused the assertion and try to figure out why the two values weren't equal. There might be something wrong with the logic in the code or a typo that is causing the two values to not be equal. Once you figure out the cause of the problem, you will be able to update the code to get the correct result."},{"command_executed":"tests/test_meetings.py ","error":"==================================== test session starts =====================================\nplatform darwin -- Python 3.8.5, pytest-7.1.2, pluggy-1.0.0\nrootdir: /Users/demouser/meetingsproject, configfile: pyproject.toml\ncollected 596 items                                                                          \n\ntests/test_meetings.py F........................................................ [  9%]\n...................................................................................... [ 23%]\n...................................................................................... [ 38%]\n...................................................................................... [ 52%]\n...................................................................................... [ 67%]\n...................................................................................... [ 81%]\n...................................................................................... [ 96%]\n.......................                                                                [100%]\n\n========================================== FAILURES ==========================================\n______________________________________ test_item_count _______________________________________\n\n    def test_item_count():\n>       assert len(parsed_items) == 3423\nE       AssertionError: assert 584 == 3423\nE        +  where 584 = len([{'all_day': False,\\n 'classification': 'City Council',\\n 'created': FakeDatetime(2022, 3, 1, 0, 0),\\n 'description': '',...passed',\\n 'time_notes': '',\\n 'title': 'Regular City Council Meeting',\\n 'updated': FakeDatetime(2022, 3, 1, 0, 0)}, ...])\n\ntests/test_meetings.py:34: AssertionError\n================================== short test summary info ===================================\nFAILED tests/test_meetings.py::test_item_count - AssertionError: assert 584 == 3423\n=============================== 1 failed, 595 passed in 4.92s ================================\n","prompt":"I tried running this pytest unit test:\n        tests/test_meetings.py \n        and received error message:\n        ==================================== test session starts =====================================\nplatform darwin -- Python 3.8.5, pytest-7.1.2, pluggy-1.0.0\nrootdir: /Users/demouser/meetingsproject, configfile: pyproject.toml\ncollected 596 items                                                                          \n\ntests/test_meetings.py F........................................................ [  9%]\n...................................................................................... [ 23%]\n...................................................................................... [ 38%]\n...................................................................................... [ 52%]\n...................................................................................... [ 67%]\n...................................................................................... [ 81%]\n...................................................................................... [ 96%]\n.......................                                                                [100%]\n\n========================================== FAILURES ==========================================\n______________________________________ test_item_count _______________________________________\n\n    def test_item_count():\n>       assert len(parsed_items) == 3423\nE       AssertionError: assert 584 == 3423\nE        +  where 584 = len([{'all_day': False,\\n 'classification': 'City Council',\\n 'created': FakeDatetime(2022, 3, 1, 0, 0),\\n 'description': '',...passed',\\n 'time_notes': '',\\n 'title': 'Regular City Council Meeting',\\n 'updated': FakeDatetime(2022, 3, 1, 0, 0)}, ...])\n\ntests/test_meetings.py:34: AssertionError\n================================== short test summary info ===================================\nFAILED tests/test_meetings.py::test_item_count - AssertionError: assert 584 == 3423\n=============================== 1 failed, 595 passed in 4.92s ================================\n\n        Help me understand this error and explain how I can solve this error.","output":"\n\nThis error message is telling you that the test you were running failed, because the assertion that you made -- asserting that the length of the parsed_items list was equal to 3423 -- wasn't true. The error states that the actual length was 584 instead of 3423.\n\nTo solve this error, you will need to identify why the assertion was not true. If the parsed_items list was generated based on data from an external source (e.g. a database query or a remote API request), then you may need to review the query/request to determine why it is generating fewer items than you expect. If the list is being generated by code you wrote, you may need to review the code to identify any errors that could be causing it to produce an incorrect result.\n\nOnce you have identified the underlying cause, you will need to address it in order to ensure that the assertion is true and that your test passes."},{"command_executed":"search openstates ","error":"ERROR: Exception:\nTraceback (most recent call last):\n  File \"/Users/demouser/miniconda3/lib/python3.8/site-packages/pip/_internal/cli/base_command.py\", line 228, in _main\n    status = self.run(options, args)\n  File \"/Users/demouser/miniconda3/lib/python3.8/site-packages/pip/_internal/commands/search.py\", line 60, in run\n    pypi_hits = self.search(query, options)\n  File \"/Users/demouser/miniconda3/lib/python3.8/site-packages/pip/_internal/commands/search.py\", line 80, in search\n    hits = pypi.search({'name': query, 'summary': query}, 'or')\n  File \"/Users/demouser/miniconda3/lib/python3.8/xmlrpc/client.py\", line 1109, in __call__\n    return self.__send(self.__name, args)\n  File \"/Users/demouser/miniconda3/lib/python3.8/xmlrpc/client.py\", line 1450, in __request\n    response = self.__transport.request(\n  File \"/Users/demouser/miniconda3/lib/python3.8/site-packages/pip/_internal/network/xmlrpc.py\", line 45, in request\n    return self.parse_response(response.raw)\n  File \"/Users/demouser/miniconda3/lib/python3.8/xmlrpc/client.py\", line 1341, in parse_response\n    return u.close()\n  File \"/Users/demouser/miniconda3/lib/python3.8/xmlrpc/client.py\", line 655, in close\n    raise Fault(**self._stack[0])\nxmlrpc.client.Fault: <Fault -32500: \"RuntimeError: PyPI no longer supports 'pip search' (or XML-RPC search). Please use https://pypi.org/search (via a browser) instead. See https://warehouse.pypa.io/api-reference/xml-rpc.html#deprecated-methods for more information.\">\n","prompt":"I tried running this pip unit test:\n        search openstates \n        and received error message:\n        ERROR: Exception:\nTraceback (most recent call last):\n  File \"/Users/demouser/miniconda3/lib/python3.8/site-packages/pip/_internal/cli/base_command.py\", line 228, in _main\n    status = self.run(options, args)\n  File \"/Users/demouser/miniconda3/lib/python3.8/site-packages/pip/_internal/commands/search.py\", line 60, in run\n    pypi_hits = self.search(query, options)\n  File \"/Users/demouser/miniconda3/lib/python3.8/site-packages/pip/_internal/commands/search.py\", line 80, in search\n    hits = pypi.search({'name': query, 'summary': query}, 'or')\n  File \"/Users/demouser/miniconda3/lib/python3.8/xmlrpc/client.py\", line 1109, in __call__\n    return self.__send(self.__name, args)\n  File \"/Users/demouser/miniconda3/lib/python3.8/xmlrpc/client.py\", line 1450, in __request\n    response = self.__transport.request(\n  File \"/Users/demouser/miniconda3/lib/python3.8/site-packages/pip/_internal/network/xmlrpc.py\", line 45, in request\n    return self.parse_response(response.raw)\n  File \"/Users/demouser/miniconda3/lib/python3.8/xmlrpc/client.py\", line 1341, in parse_response\n    return u.close()\n  File \"/Users/demouser/miniconda3/lib/python3.8/xmlrpc/client.py\", line 655, in close\n    raise Fault(**self._stack[0])\nxmlrpc.client.Fault: <Fault -32500: \"RuntimeError: PyPI no longer supports 'pip search' (or XML-RPC search). Please use https://pypi.org/search (via a browser) instead. See https://warehouse.pypa.io/api-reference/xml-rpc.html#deprecated-methods for more information.\">\n\n        Help me understand this error and explain how I can solve this error.","output":"\n\nThis error is telling you that the \"pip search\" command has been deprecated and is no longer supported. As the error message suggests, you should use the https://pypi.org/search URL to search for packages instead of using the \"pip search\" command. By visiting the URL in a browser, you will be able to search for packages and find the one you are looking for."},{"command_executed":"i react-swipeable-views ","error":"npm ERR! code ERESOLVE\nnpm ERR! ERESOLVE unable to resolve dependency tree\nnpm ERR! \nnpm ERR! While resolving: web@0.1.0\nnpm ERR! Found: react@18.2.0\nnpm ERR! node_modules/react\nnpm ERR!   react@\"^18.2.0\" from the root project\nnpm ERR! \nnpm ERR! Could not resolve dependency:\nnpm ERR! peer react@\"^15.3.0 || ^16.0.0 || ^17.0.0\" from react-swipeable-views@0.14.0\nnpm ERR! node_modules/react-swipeable-views\nnpm ERR!   react-swipeable-views@\"*\" from the root project\nnpm ERR! \nnpm ERR! Fix the upstream dependency conflict, or retry\nnpm ERR! this command with --force, or --legacy-peer-deps\nnpm ERR! to accept an incorrect (and potentially broken) dependency resolution.\nnpm ERR! \nnpm ERR! See /home/demouser/.npm/eresolve-report.txt for a full report.\n\nnpm ERR! A complete log of this run can be found in:\nnpm ERR!     /home/demouser/.npm/_logs/2022-08-04T16_50_51_600Z-debug-0.log\n","prompt":"I tried running this npm unit test:\n        i react-swipeable-views \n        and received error message:\n        npm ERR! code ERESOLVE\nnpm ERR! ERESOLVE unable to resolve dependency tree\nnpm ERR! \nnpm ERR! While resolving: web@0.1.0\nnpm ERR! Found: react@18.2.0\nnpm ERR! node_modules/react\nnpm ERR!   react@\"^18.2.0\" from the root project\nnpm ERR! \nnpm ERR! Could not resolve dependency:\nnpm ERR! peer react@\"^15.3.0 || ^16.0.0 || ^17.0.0\" from react-swipeable-views@0.14.0\nnpm ERR! node_modules/react-swipeable-views\nnpm ERR!   react-swipeable-views@\"*\" from the root project\nnpm ERR! \nnpm ERR! Fix the upstream dependency conflict, or retry\nnpm ERR! this command with --force, or --legacy-peer-deps\nnpm ERR! to accept an incorrect (and potentially broken) dependency resolution.\nnpm ERR! \nnpm ERR! See /home/demouser/.npm/eresolve-report.txt for a full report.\n\nnpm ERR! A complete log of this run can be found in:\nnpm ERR!     /home/demouser/.npm/_logs/2022-08-04T16_50_51_600Z-debug-0.log\n\n        Help me understand this error and explain how I can solve this error.","output":"\n\nThis error occurs when the dependencies of a package do not match with the versions found in the node_modules directory. It is most likely caused by outdated modules in the node_modules directory.\n\nTo solve this error, you should uninstall and reinstall the package using npm (or yarn) with the right version numbers specified as part of the command. \n\nFor example:\n\nnpm install react@^15.3.0 react-swipeable-views@0.14.0\n\nThis will ensure that you are getting the right version of the modules needed for your package. You may also need to delete and reinstall the package dependencies inside the node_modules folder, or clear your npm cache in order to force a reinstall of the latest versions. \n\nIf the issue persists, you may need to consult the official documentation for the package, or reach out to the maintainers for assistance."}]}